<?xml version='1.0'?>
<sdf version='1.6'>
    <model name="delta_robot">
    <pose>0 0 0.05 0 0 0</pose>
    

    <link name="base">
        <inertial>
            <mass>50</mass>
            <!--<inertia>
                <ixx>0.085</ixx>
                <ixy>0</ixy>
                <ixz>0</ixz>
                <iyy>0.085</iyy>
                <iyz>0</iyz>
                <izz>0.166</izz>
            </inertia>-->
        </inertial>
        <collision name="base_collision">
            <pose>0 0 0 0 0 0</pose>
            <geometry>
                <box>
                    <size>1 1 0.1</size>
                </box>
            </geometry>
        </collision>
        <visual name="base_visual">
            <pose>0 0 0 0 0 0</pose>
            <geometry>
                <box>
                    <size>1 1 0.1</size>
                </box>
            </geometry>
        </visual>

        <collision name="column_collision">
            <pose>0 0 0.45 0 0 0</pose>
            <geometry>
                <box>
                    <size>0.02 0.02 1</size>
                </box>
            </geometry>
        </collision>
        <visual name="column_visual">
            <pose>0 0 0.45 0 0 0</pose>
            <geometry>
                <box>
                    <size>0.02 0.02 1</size>
                </box>
            </geometry>
        </visual>
    </link>

    <link name="forearm">
        <inertial>
            <mass>1.2</mass>
            <!--<inertia>
                <ixx>0.00007</ixx>
                <ixy>0</ixy>
                <ixz>0</ixz>
                <iyy>0.0075</iyy>
                <iyz>0</iyz>
                <izz>0.0075</izz>
            </inertia>-->
        </inertial>
        <collision name="forearm_collision">
            <pose>0.14 0 0.96 0 0 0</pose>
            <geometry>
                <box>
                    <size>0.3 0.02 0.02</size>
                </box>
            </geometry>
        </collision>
        <visual name="forearm_visual">
            <pose>0.14 0 0.96 0 0 0</pose>
            <geometry>
                <box>
                    <size>0.3 0.02 0.02</size>
                </box>
            </geometry>
        </visual>
    </link>

    <link name="arm">
        <inertial>
            <mass>1.2</mass>
            <!--<inertia>
                <ixx>0.0087</ixx>
                <ixy>0</ixy>
                <ixz>0</ixz>
                <iyy>0.0188</iyy>
                <iyz>0</iyz>
                <izz>0.01021</izz>
            </inertia>-->
        </inertial>
        <collision name="arm1_collision">
            <pose>0.14 0 0.98 0 0 0</pose>
            <geometry>
                <box>
                    <size>0.3 0.02 0.02</size>
                </box>
            </geometry>
        </collision>
        <visual name="arm1_visual">
            <pose>0.14 0 0.98 0 0 0</pose>
            <geometry>
                <box>
                    <size>0.3 0.02 0.02</size>
                </box>
            </geometry>
        </visual>
        <collision name="arm2_collision">
            <pose>0.3 0 0.84 0 0 0</pose>
            <geometry>
                <box>
                    <size>0.02 0.02 0.3</size>
                </box>
            </geometry>
        </collision>
        <visual name="arm2_visual">
            <pose>0.3 0 0.84 0 0 0</pose>
            <geometry>forearm_shaft1
                <box>
                    <size>0.02 0.02 0.3</size>
                </box>
            </geometry>
        </visual>
    </link>

    <link name="gripper">
        <inertial>
            <mass>0.064</mass>
            <!--<inertia>
                <ixx>0.008451</ixx>
                <ixy>0</ixy>
                <ixz>0</ixz>
                <iyy>0.008434</iyy>
                <iyz>0</iyz>
                <izz>0.00009635</izz>
            </inertia>-->
        </inertial>
        <collision name="arm3_collision">
            <pose>0.32 0 0.84 0 0 0</pose>
            <geometry>
                <box>
                    <size>0.02 0.02 0.3</size>
                </box>
            </geometry>
        </collision>
        <visual name="arm3_visual">
            <pose>0.32 0 0.84 0 0 0</pose>
            <geometry>
                <box>
                    <size>0.02 0.02 0.3</size>
                </box>
            </geometry>
        </visual>

        <collision name="gripper1_collision">
            <pose>0.32 0 0.6875 0 0 2.09</pose>
            <geometry>
                <box>
                    <size>0.08 0.01 0.005</size>
                </box>
            </geometry>
        </collision>
        <visual name="gripper1_visual">
            <pose>0.32 0 0.6875 0 0 2.09</pose>
            <geometry>
                <box>
                    <size>0.08 0.01 0.005</size>
                </box>
            </geometry>
        </visual>


        <collision name="gripper2_collision">
            <pose>0.32 0 0.6875 0 0 -2.09</pose>
            <geometry>
                <box>
                    <size>0.08 0.01 0.005</size>
                </box>
            </geometry>
        </collision>
        <visual name="gripper2_visual">
            <pose>0.32 0 0.6875 0 0 -2.09</pose>
            <geometry>
                <box>
                    <size>0.08 0.01 0.005</size>
                </box>
            </geometry>
        </visual>
    </link>

    <joint name="theta" type="revolute">
        <pose>0 0 0.95 0 0 0</pose>
        <parent>base</parent>
        <child>forearm</child>
        <axis>
            <xyz>0 0 1</xyz>
        </axis>
    </joint>


    <joint name="radius" type="prismatic">
        <pose>0.14 0 0.97 0 0 0</pose>
        <parent>forearm</parent>
        <child>arm</child>
        <axis>
            <xyz>1 0 0</xyz>
            <initial_position>0.04</initial_position>
            <limit>
                <lower>0</lower>
                <upper>0.3</upper>
            </limit>
        </axis>
    </joint>

    <joint name="height" type="prismatic">
        <pose>0.31 0 0.84 3.14 0 0</pose>
        <parent>arm</parent>
        <child>gripper</child>
        <axis>
            <xyz>0 0 1</xyz>
            <initial_position>0.04</initial_position>
            <limit>
               <lower>0</lower>
               <upper>0.3</upper>
            </limit>
        </axis>
    </joint>
    </model>
</sdf>