<?xml version='1.0'?>
<sdf version='1.7'>
  <model name="robot">
    <static>false</static>
    <!-- <pose>0 0 0.0225 0 0 0</pose> -->
    <link name='chassis'>
      <pose>0 0 0.0225 0 0 0</pose>
      <inertial>
        <pose>0 0 -0.0225 0 0 0</pose>
        <mass>10</mass>
      </inertial>

      <!-- <sensor name="ultrasonic" type="lidar">
            <pose>0.06 0 0 0 -1.5707 0</pose>
            <always_on>1</always_on>
            <visualize>1</visualize>
            <lidar>
              <scan>
                <horizontal>
                  <samples>1</samples>
                  <resolution>1</resolution>
                  <min_angle>0</min_angle>
                  <max_angle>0</max_angle>
                </horizontal>
                <vertical>
                  <samples>1</samples>
                  <resolution>1</resolution>
                  <min_angle>0</min_angle>
                  <max_angle>0</max_angle>
                </vertical>
              </scan>
              <range>
                <min>0.01</min>
                <max>0.1</max>
              </range>
            </lidar>
          </sensor> -->

      <collision name='collision'>
        <geometry>
          <!-- <box>
                <size>.4 .2 .1</size>
              </box> -->
          <cylinder>
            <radius>0.05</radius>
            <length>0.005</length>
          </cylinder>
        </geometry>
      </collision>

      <visual name='front_marker'>
        <pose>0.043 0 0.001</pose>
        <material>
          <ambient>0.1 0.1 0.1 1</ambient>
          <diffuse>0.1 0.1 0.2 1</diffuse>
          <specular>0 0 0 0</specular>
          <emissive>0 0 0 1</emissive>
        </material>
        <geometry>
          <cylinder>
            <radius>0.005</radius>
            <length>0.005</length>
          </cylinder>
        </geometry>
      </visual>

      <visual name='visual'>
        <geometry>
          <!-- <box>
                <size>.4 .2 .1</size>
              </box> -->
          <cylinder>
            <radius>0.05</radius>
            <length>0.005</length>
          </cylinder>
        </geometry>
      </visual>

      <collision name='caster_front_collision'>
        <pose>0.03 0 -0.0123 0 0 0</pose>
        <geometry>
          <sphere>
            <radius>.01</radius>
          </sphere>
        </geometry>

        <surface>
          <friction>
            <ode>
              <mu>0</mu>
              <mu2>0</mu2>
              <slip1>1.0</slip1>
              <slip2>1.0</slip2>
            </ode>
              
          </friction>
        </surface>
      </collision>

      <visual name='caster_front_visual'>
        <pose>0.03 0 -0.0123 0 0 0</pose>
        <geometry>
          <sphere>
            <radius>.01</radius>
          </sphere>
        </geometry>
      </visual>

      <collision name='caster_back_collision'>
        <pose>-0.03 0 -0.0125 0 0 0</pose>
        <geometry>
          <sphere>
            <radius>.01</radius>
          </sphere>
        </geometry>

        <surface>
          <friction>
            <ode>
              <mu>0</mu>
              <mu2>0</mu2>
              <slip1>1.0</slip1>
              <slip2>1.0</slip2>
            </ode>
          </friction>
        </surface>
      </collision>

      <visual name='caster_back_visual'>
        <pose>-0.03 0 -0.0125 0 0 0</pose>
        <geometry>
          <sphere>
            <radius>.01</radius>
          </sphere>
        </geometry>
      </visual>
    
							<sensor name="ultrasonic" type="ray">
								<!-- <pose>0.048 0.0 -0.0025 0.0 1.5707499980926514 0.0</pose> -->
                <pose>0.048 0.0 -0.0025 0.0 0.7853981633974483 0.0</pose>
								<visualize>true</visualize>
								<always_on>1</always_on>
								<update_rate>30.0</update_rate>
								<ray>
									<scan>
										<horizontal>
											<samples>10</samples>
											<resolution>10.0</resolution>
										</horizontal>
										<vertical>
											<samples>10</samples>
											<resolution>10.0</resolution>
										</vertical>
									</scan>
									<range>
										<min>0.01</min>
										<max>0.05</max>
									</range>
								</ray>
							</sensor>

    <sensor type="imu" name="acc_left">
      <pose>0 0.045 0.00225 0 0 0</pose>
      <visualize>true</visualize>
      <always_on>1</always_on>
			<update_rate>1000</update_rate>
      <!-- <imu>
        <orientation_reference_frame>
          <localization>GRAV_DOWN</localization>
          <grav_dir_x parent_frame="chassis"></grav_dir_x>
        </orientation_reference_frame>
      </imu> -->
    </sensor>

    <sensor type="imu" name="acc_right">
      <pose>0 -0.045 0.00225 0 0 0</pose>
      <visualize>true</visualize>
      <always_on>1</always_on>
			<update_rate>1000</update_rate>
      <!-- <imu>
        <orientation_reference_frame>
          <localization>GRAV_DOWN</localization>
          <grav_dir_x parent_frame="chassis"></grav_dir_x>
        </orientation_reference_frame>
      </imu> -->
    </sensor>
    </link>

    <link name="spine">
      <pose>0 0 0.0225 0 0 0</pose>
      <!-- <inertial>
        <mass>1</mass>
      </inertial> -->
      <visual name='spine_visual'>
        <pose>0 0 -0.01 0 0 0</pose>
        <geometry>
          <box>
            <size>.04 .07 .015</size>
          </box>
        </geometry>
      </visual>

      <collision name='spine_collision'>
        <pose>0 0 -0.01 0 0 0</pose>
        <geometry>
          <box>
            <size>.04 .07 .015</size>
          </box>
        </geometry>
      </collision>
    </link>

    <joint type="fixed" name='top_spine'>
      <parent>chassis</parent>
      <child>spine</child>
    </joint>

    <link name="left_wheel">
      <!-- <pose>0.0 0.04 -0.0125 1.5707 0 0</pose> -->
      <pose>0.0 0.04 0.01 0 1.5707 1.5707</pose>
      <inertial>
        <mass>0.1</mass>
      </inertial>
      <collision name="collision">
                     <surface>
            <friction>
              <ode>
                <mu>100000</mu>
                <mu2>100000</mu2>
              </ode>
            </friction>
            <bounce/>
          </surface>
        <geometry>
          <cylinder>
            <radius>.01</radius>
            <length>.005</length>
          </cylinder>
        </geometry>
      </collision>
      <visual name="visual">
        <geometry>
          <cylinder>
            <radius>.01</radius>
            <length>.005</length>
          </cylinder>
        </geometry>
      </visual>
    </link>

    <link name="right_wheel">
      <!-- <pose>0.0 -0.04 -0.0125 1.5707 0 0</pose> -->
      <pose>0.0 -0.04 0.01 0 1.5707 1.5707</pose>
      <inertial>
        <mass>0.1</mass>
      </inertial>
      <collision name="collision">
                     <surface>
            <contact>
              <collide_bitmask>65535</collide_bitmask>
              <ode/>
            </contact>
            <friction>
              <ode>
                <mu>100000</mu>
                <mu2>100000</mu2>
              </ode>
            </friction>
            <bounce/>
          </surface>
        <geometry>
          <cylinder>
            <radius>.01</radius>
            <length>.005</length>
          </cylinder>
        </geometry>
      </collision>
      <visual name="visual">
        <geometry>
          <cylinder>
            <radius>.01</radius>
            <length>.005</length>
          </cylinder>
        </geometry>
      </visual>
    </link>

    <joint type="revolute" name="left_wheel_hinge">
      <pose>0.0 0.0 -0.005 0 0</pose>
      <child>left_wheel</child>
      <parent>chassis</parent>
      <axis>
        <xyz>0 0 1</xyz>
      </axis>
    </joint>

    <joint type="revolute" name="right_wheel_hinge">
      <pose>0.0 0.0 0.005 0 0 0</pose>
      <child>right_wheel</child>
      <parent>chassis</parent>
      <axis>
        <xyz>0 0 1</xyz>
      </axis>
    </joint>




    <plugin name="controller" filename="robot/plugins/simple_controller/build/libcontroller.so"/>



  </model>
</sdf>
